Workbook

Sheet kwitansi
J1: =+K1&"/"&L1&"/"&M1&"/"&N1&"/"&O1 -> 224/TKMPN/WKM/X/2026 | K1: 224 | L1: TKMPN | M1: WKM | N1: X | O1: 2026
L2: Tahap I/IV : SPK Nomor : WKM/089/KT/X/2009
B3: PT WASKITA KARYA (PERSERO) Tbk
C5: ="#"&Sheet1!L4&Sheet1!M4&Sheet1!N4&Sheet1!O4&Sheet1!P4&Sheet1!Q4&Sheet1!R4&Sheet1!S4&Sheet1!T4&"Rupiah"&"#" -> #Lima Puluh Tujuh Juta Empat Ratus Empat Puluh Dua Ribu Lima Ratus Rupiah#
B7: Temu Karya Mutu & Produktivitas Nasional (TKMPN) XXX - 2026
B8: Padang, 23 - 27 November 2026
B9: Jumlah peserta 9 orang
C14: PT PERTAMINA GAS TAHUN 2012
C15: pada tanggal 11 - 13 Juli 2012 di Hotel Novotel Solo
J16: 46308
A19: 57442500 | J19: Indah Budiwati
J20: Bendahara

Sheet Sheet1
L1: Ratusan | M1: Puluhan | O1: Ratusan | P1: Puluhan
L2: Juta | M2: Juta | N2: Jutaan | O2: Ribu | P2: Ribu | Q2: Ribuan | R2: Ratusan | S2: Puluhan | T2: Satuan
L4: =+IF(RIGHT(kwitansi!A19,9)-RIGHT(kwitansi!A19,8)=0,"",IF(RIGHT(kwitansi!A19,8)-RIGHT(kwitansi!A19,6)=0,VLOOKUP(RIGHT(kwitansi!A19,9)-RIGHT(kwitansi!A19,8),Sheet2!$B$4:$C$12,2)&"Juta ",VLOOKUP(RIGHT(kwitansi!A19,9)-RIGHT(kwitansi!A19,8),Sheet2!$B$4:$C$12,2))) | M4: =+IF(RIGHT(kwitansi!A19,8)-RIGHT(kwitansi!A19,7)=0,"",IF(AND(RIGHT(kwitansi!A19,8)-RIGHT(kwitansi!A19,7)=10000000,RIGHT(kwitansi!A19,7)-RIGHT(kwitansi!A19,6)>0),VLOOKUP(RIGHT(kwitansi!A19,8)-RIGHT(kwitansi!A19,6),Sheet2!$D$4:$E$12,2),VLOOKUP(RIGHT(kwitansi!A19,8)-RIGHT(kwitansi!A19,7),Sheet2!$F$4:$G$12,2)))&IF(AND(RIGHT(kwitansi!A19,7)-RIGHT(kwitansi!A19,6)=0,RIGHT(kwitansi!A19,8)-RIGHT(kwitansi!A19,7)>0),"Juta ","") -> Lima Puluh | N4: =+IF(RIGHT(kwitansi!A19,7)-RIGHT(kwitansi!A19,6)=0,"",IF(AND(RIGHT(kwitansi!A19,8)-RIGHT(kwitansi!A19,7)=10000000,RIGHT(kwitansi!A19,7)-RIGHT(kwitansi!A19,6)>0),"",VLOOKUP(RIGHT(kwitansi!A19,7)-RIGHT(kwitansi!A19,6),Sheet2!$H$4:$I$12,2))) -> Tujuh Juta | O4: =+IF(RIGHT(kwitansi!A19,6)-RIGHT(kwitansi!A19,5)=0,"",IF(AND(RIGHT(kwitansi!A19,5)-RIGHT(kwitansi!A19,3)=0,RIGHT(kwitansi!A19,6)-RIGHT(kwitansi!A19,5)>0),VLOOKUP(RIGHT(kwitansi!A19,6)-RIGHT(kwitansi!A19,5),Sheet2!$J$4:$K$12,2)&"Ribu ",VLOOKUP(RIGHT(kwitansi!A19,6)-RIGHT(kwitansi!A19,5),Sheet2!$J$4:$K$12,2))) -> Empat Ratus | P4: =+IF(RIGHT(kwitansi!A19,5)-RIGHT(kwitansi!A19,4)=0,"",IF(AND(RIGHT(kwitansi!A19,5)-RIGHT(kwitansi!A19,4)=10000,VALUE(RIGHT(kwitansi!A19,4))>=1000),VLOOKUP(RIGHT(kwitansi!A19,5)-RIGHT(kwitansi!A19,3),Sheet2!$L$4:$M$12,2),VLOOKUP(RIGHT(kwitansi!A19,5)-RIGHT(kwitansi!A19,4),Sheet2!$N$4:$O$12,2)))&IF(AND(VALUE(RIGHT(kwitansi!A19,4))<1000,RIGHT(kwitansi!A19,5)-RIGHT(kwitansi!A19,4)>0),"Ribu ","") -> Empat Puluh | Q4: =+IF(RIGHT(kwitansi!A19,4)-RIGHT(kwitansi!A19,3)=0,"",IF(RIGHT(kwitansi!A19,5)-RIGHT(kwitansi!A19,4)=10000,"",IF(AND(VALUE(RIGHT(kwitansi!A19,6))>=20000,VALUE(RIGHT(kwitansi!A19,6)-RIGHT(kwitansi!A19,5))<=900000),VLOOKUP(RIGHT(kwitansi!A19,4)-RIGHT(kwitansi!A19,3),Sheet2!$P$4:$Q$12,2),"Seribu "))) -> Dua Ribu | R4: =+IF(RIGHT(kwitansi!A19,3)-RIGHT(kwitansi!A19,2)=0,"",VLOOKUP(RIGHT(kwitansi!A19,3)-RIGHT(kwitansi!A19,2),Sheet2!$R$4:$S$12,2)) -> Lima Ratus | S4: =+IF(RIGHT(kwitansi!A19,2)-RIGHT(kwitansi!A19,1)=0,"",IF(AND(RIGHT(kwitansi!A19,2)-RIGHT(kwitansi!A19,1)=10,VALUE(RIGHT(kwitansi!A19,1))>0),VLOOKUP(VALUE(RIGHT(kwitansi!A19,2)),Sheet2!$X$4:$Y$12,2),VLOOKUP(RIGHT(kwitansi!A19,2)-RIGHT(kwitansi!A19,1),Sheet2!$T$4:$U$12,2))) | T4: =+IF(RIGHT(kwitansi!A19,2)-RIGHT(kwitansi!A19,1)=10,"",IF(VALUE(RIGHT(kwitansi!A19,1))=0,"",VLOOKUP(VALUE(RIGHT(kwitansi!A19,1)),Sheet2!$V$4:$W$12,2)))
I5: 95055 | J5: =L5&M5&N5&O5&P5&Q5&R5&S5&T5&"Rupiah" -> Sembilan Puluh Lima Ribu Lima Puluh Lima Rupiah | L5: =+IF(RIGHT(I5,9)-RIGHT(I5,8)=0,"",IF(RIGHT(I5,8)-RIGHT(I5,6)=0,VLOOKUP(RIGHT(I5,9)-RIGHT(I5,8),Sheet2!$B$4:$C$12,2)&"Juta ",VLOOKUP(RIGHT(I5,9)-RIGHT(I5,8),Sheet2!$B$4:$C$12,2))) | M5: =+IF(RIGHT(I5,8)-RIGHT(I5,7)=0,"",IF(AND(RIGHT(I5,8)-RIGHT(I5,7)=10000000,RIGHT(I5,7)-RIGHT(I5,6)>0),VLOOKUP(RIGHT(I5,8)-RIGHT(I5,6),Sheet2!$D$4:$E$12,2),VLOOKUP(RIGHT(I5,8)-RIGHT(I5,7),Sheet2!$F$4:$G$12,2)))&IF(AND(RIGHT(I5,7)-RIGHT(I5,6)=0,RIGHT(I5,8)-RIGHT(I5,7)>0),"Juta ","") | N5: =+IF(RIGHT(I5,7)-RIGHT(I5,6)=0,"",IF(AND(RIGHT(I5,8)-RIGHT(I5,7)=10000000,RIGHT(I5,7)-RIGHT(I5,6)>0),"",VLOOKUP(RIGHT(I5,7)-RIGHT(I5,6),Sheet2!$H$4:$I$12,2))) | O5: =+IF(RIGHT(I5,6)-RIGHT(I5,5)=0,"",IF(AND(RIGHT(I5,5)-RIGHT(I5,3)=0,RIGHT(I5,6)-RIGHT(I5,5)>0),VLOOKUP(RIGHT(I5,6)-RIGHT(I5,5),Sheet2!$J$4:$K$12,2)&"Ribu ",VLOOKUP(RIGHT(I5,6)-RIGHT(I5,5),Sheet2!$J$4:$K$12,2))) | P5: =+IF(RIGHT(I5,5)-RIGHT(I5,4)=0,"",IF(AND(RIGHT(I5,5)-RIGHT(I5,4)=10000,VALUE(RIGHT(I5,4))>=1000),VLOOKUP(RIGHT(I5,5)-RIGHT(I5,3),Sheet2!$L$4:$M$12,2),VLOOKUP(RIGHT(I5,5)-RIGHT(I5,4),Sheet2!$N$4:$O$12,2)))&IF(AND(VALUE(RIGHT(I5,4))<1000,RIGHT(I5,5)-RIGHT(I5,4)>0),"Ribu ","") -> Sembilan Puluh | Q5: =+IF(RIGHT(I5,4)-RIGHT(I5,3)=0,"",IF(RIGHT(I5,5)-RIGHT(I5,4)=10000,"",IF(AND(VALUE(RIGHT(I5,6))>=20000,VALUE(RIGHT(I5,6)-RIGHT(I5,5))<=900000),VLOOKUP(RIGHT(I5,4)-RIGHT(I5,3),Sheet2!$P$4:$Q$12,2),"Seribu "))) -> Lima Ribu | R5: =+IF(RIGHT(I5,3)-RIGHT(I5,2)=0,"",VLOOKUP(RIGHT(I5,3)-RIGHT(I5,2),Sheet2!$R$4:$S$12,2)) | S5: =+IF(RIGHT(I5,2)-RIGHT(I5,1)=0,"",IF(AND(RIGHT(I5,2)-RIGHT(I5,1)=10,VALUE(RIGHT(I5,1))>0),VLOOKUP(VALUE(RIGHT(I5,2)),Sheet2!$X$4:$Y$12,2),VLOOKUP(RIGHT(I5,2)-RIGHT(I5,1),Sheet2!$T$4:$U$12,2))) -> Lima Puluh | T5: =+IF(RIGHT(I5,2)-RIGHT(I5,1)=10,"",IF(VALUE(RIGHT(I5,1))=0,"",VLOOKUP(VALUE(RIGHT(I5,1)),Sheet2!$V$4:$W$12,2))) -> Lima
I6: 10054400 | J6: =L6&M6&N6&O6&P6&Q6&R6&S6&T6&"Rupiah" -> Sepuluh Juta Lima Puluh Empat Ribu Empat Ratus Rupiah | L6: =+IF(RIGHT(I6,9)-RIGHT(I6,8)=0,"",IF(RIGHT(I6,8)-RIGHT(I6,6)=0,VLOOKUP(RIGHT(I6,9)-RIGHT(I6,8),Sheet2!$B$4:$C$12,2)&"Juta ",VLOOKUP(RIGHT(I6,9)-RIGHT(I6,8),Sheet2!$B$4:$C$12,2))) | M6: =+IF(RIGHT(I6,8)-RIGHT(I6,7)=0,"",IF(AND(RIGHT(I6,8)-RIGHT(I6,7)=10000000,RIGHT(I6,7)-RIGHT(I6,6)>0),VLOOKUP(RIGHT(I6,8)-RIGHT(I6,6),Sheet2!$D$4:$E$12,2),VLOOKUP(RIGHT(I6,8)-RIGHT(I6,7),Sheet2!$F$4:$G$12,2)))&IF(AND(RIGHT(I6,7)-RIGHT(I6,6)=0,RIGHT(I6,8)-RIGHT(I6,7)>0),"Juta ","") -> Sepuluh Juta | N6: =+IF(RIGHT(I6,7)-RIGHT(I6,6)=0,"",IF(AND(RIGHT(I6,8)-RIGHT(I6,7)=10000000,RIGHT(I6,7)-RIGHT(I6,6)>0),"",VLOOKUP(RIGHT(I6,7)-RIGHT(I6,6),Sheet2!$H$4:$I$12,2))) | O6: =+IF(RIGHT(I6,6)-RIGHT(I6,5)=0,"",IF(AND(RIGHT(I6,5)-RIGHT(I6,3)=0,RIGHT(I6,6)-RIGHT(I6,5)>0),VLOOKUP(RIGHT(I6,6)-RIGHT(I6,5),Sheet2!$J$4:$K$12,2)&"Ribu ",VLOOKUP(RIGHT(I6,6)-RIGHT(I6,5),Sheet2!$J$4:$K$12,2))) | P6: =+IF(RIGHT(I6,5)-RIGHT(I6,4)=0,"",IF(AND(RIGHT(I6,5)-RIGHT(I6,4)=10000,VALUE(RIGHT(I6,4))>=1000),VLOOKUP(RIGHT(I6,5)-RIGHT(I6,3),Sheet2!$L$4:$M$12,2),VLOOKUP(RIGHT(I6,5)-RIGHT(I6,4),Sheet2!$N$4:$O$12,2)))&IF(AND(VALUE(RIGHT(I6,4))<1000,RIGHT(I6,5)-RIGHT(I6,4)>0),"Ribu ","") -> Lima Puluh | Q6: =+IF(RIGHT(I6,4)-RIGHT(I6,3)=0,"",IF(RIGHT(I6,5)-RIGHT(I6,4)=10000,"",IF(AND(VALUE(RIGHT(I6,6))>=20000,VALUE(RIGHT(I6,6)-RIGHT(I6,5))<=900000),VLOOKUP(RIGHT(I6,4)-RIGHT(I6,3),Sheet2!$P$4:$Q$12,2),"Seribu "))) -> Empat Ribu | R6: =+IF(RIGHT(I6,3)-RIGHT(I6,2)=0,"",VLOOKUP(RIGHT(I6,3)-RIGHT(I6,2),Sheet2!$R$4:$S$12,2)) -> Empat Ratus | S6: =+IF(RIGHT(I6,2)-RIGHT(I6,1)=0,"",IF(AND(RIGHT(I6,2)-RIGHT(I6,1)=10,VALUE(RIGHT(I6,1))>0),VLOOKUP(VALUE(RIGHT(I6,2)),Sheet2!$X$4:$Y$12,2),VLOOKUP(RIGHT(I6,2)-RIGHT(I6,1),Sheet2!$T$4:$U$12,2))) | T6: =+IF(RIGHT(I6,2)-RIGHT(I6,1)=10,"",IF(VALUE(RIGHT(I6,1))=0,"",VLOOKUP(VALUE(RIGHT(I6,1)),Sheet2!$V$4:$W$12,2)))
I7: 87564121 | J7: =L7&M7&N7&O7&P7&Q7&R7&S7&T7&"Rupiah" -> Delapan Puluh Tujuh Juta Lima Ratus Enam Puluh Empat Ribu Seratus Dua Puluh Satu Rupiah | L7: =+IF(RIGHT(I7,9)-RIGHT(I7,8)=0,"",IF(RIGHT(I7,8)-RIGHT(I7,6)=0,VLOOKUP(RIGHT(I7,9)-RIGHT(I7,8),Sheet2!$B$4:$C$12,2)&"Juta ",VLOOKUP(RIGHT(I7,9)-RIGHT(I7,8),Sheet2!$B$4:$C$12,2))) | M7: =+IF(RIGHT(I7,8)-RIGHT(I7,7)=0,"",IF(AND(RIGHT(I7,8)-RIGHT(I7,7)=10000000,RIGHT(I7,7)-RIGHT(I7,6)>0),VLOOKUP(RIGHT(I7,8)-RIGHT(I7,6),Sheet2!$D$4:$E$12,2),VLOOKUP(RIGHT(I7,8)-RIGHT(I7,7),Sheet2!$F$4:$G$12,2)))&IF(AND(RIGHT(I7,7)-RIGHT(I7,6)=0,RIGHT(I7,8)-RIGHT(I7,7)>0),"Juta ","") -> Delapan Puluh | N7: =+IF(RIGHT(I7,7)-RIGHT(I7,6)=0,"",IF(AND(RIGHT(I7,8)-RIGHT(I7,7)=10000000,RIGHT(I7,7)-RIGHT(I7,6)>0),"",VLOOKUP(RIGHT(I7,7)-RIGHT(I7,6),Sheet2!$H$4:$I$12,2))) -> Tujuh Juta | O7: =+IF(RIGHT(I7,6)-RIGHT(I7,5)=0,"",IF(AND(RIGHT(I7,5)-RIGHT(I7,3)=0,RIGHT(I7,6)-RIGHT(I7,5)>0),VLOOKUP(RIGHT(I7,6)-RIGHT(I7,5),Sheet2!$J$4:$K$12,2)&"Ribu ",VLOOKUP(RIGHT(I7,6)-RIGHT(I7,5),Sheet2!$J$4:$K$12,2))) -> Lima Ratus | P7: =+IF(RIGHT(I7,5)-RIGHT(I7,4)=0,"",IF(AND(RIGHT(I7,5)-RIGHT(I7,4)=10000,VALUE(RIGHT(I7,4))>=1000),VLOOKUP(RIGHT(I7,5)-RIGHT(I7,3),Sheet2!$L$4:$M$12,2),VLOOKUP(RIGHT(I7,5)-RIGHT(I7,4),Sheet2!$N$4:$O$12,2)))&IF(AND(VALUE(RIGHT(I7,4))<1000,RIGHT(I7,5)-RIGHT(I7,4)>0),"Ribu ","") -> Enam Puluh | Q7: =+IF(RIGHT(I7,4)-RIGHT(I7,3)=0,"",IF(RIGHT(I7,5)-RIGHT(I7,4)=10000,"",IF(AND(VALUE(RIGHT(I7,6))>=20000,VALUE(RIGHT(I7,6)-RIGHT(I7,5))<=900000),VLOOKUP(RIGHT(I7,4)-RIGHT(I7,3),Sheet2!$P$4:$Q$12,2),"Seribu "))) -> Empat Ribu | R7: =+IF(RIGHT(I7,3)-RIGHT(I7,2)=0,"",VLOOKUP(RIGHT(I7,3)-RIGHT(I7,2),Sheet2!$R$4:$S$12,2)) -> Seratus | S7: =+IF(RIGHT(I7,2)-RIGHT(I7,1)=0,"",IF(AND(RIGHT(I7,2)-RIGHT(I7,1)=10,VALUE(RIGHT(I7,1))>0),VLOOKUP(VALUE(RIGHT(I7,2)),Sheet2!$X$4:$Y$12,2),VLOOKUP(RIGHT(I7,2)-RIGHT(I7,1),Sheet2!$T$4:$U$12,2))) -> Dua Puluh | T7: =+IF(RIGHT(I7,2)-RIGHT(I7,1)=10,"",IF(VALUE(RIGHT(I7,1))=0,"",VLOOKUP(VALUE(RIGHT(I7,1)),Sheet2!$V$4:$W$12,2))) -> Satu
I8: 101010101 | J8: =L8&M8&N8&O8&P8&Q8&R8&S8&T8&"Rupiah" -> Seratus Satu Juta Sepuluh Ribu Seratus Satu Rupiah | L8: =+IF(RIGHT(I8,9)-RIGHT(I8,8)=0,"",IF(RIGHT(I8,8)-RIGHT(I8,6)=0,VLOOKUP(RIGHT(I8,9)-RIGHT(I8,8),Sheet2!$B$4:$C$12,2)&"Juta ",VLOOKUP(RIGHT(I8,9)-RIGHT(I8,8),Sheet2!$B$4:$C$12,2))) -> Seratus | M8: =+IF(RIGHT(I8,8)-RIGHT(I8,7)=0,"",IF(AND(RIGHT(I8,8)-RIGHT(I8,7)=10000000,RIGHT(I8,7)-RIGHT(I8,6)>0),VLOOKUP(RIGHT(I8,8)-RIGHT(I8,6),Sheet2!$D$4:$E$12,2),VLOOKUP(RIGHT(I8,8)-RIGHT(I8,7),Sheet2!$F$4:$G$12,2)))&IF(AND(RIGHT(I8,7)-RIGHT(I8,6)=0,RIGHT(I8,8)-RIGHT(I8,7)>0),"Juta ","") | N8: =+IF(RIGHT(I8,7)-RIGHT(I8,6)=0,"",IF(AND(RIGHT(I8,8)-RIGHT(I8,7)=10000000,RIGHT(I8,7)-RIGHT(I8,6)>0),"",VLOOKUP(RIGHT(I8,7)-RIGHT(I8,6),Sheet2!$H$4:$I$12,2))) -> Satu Juta | O8: =+IF(RIGHT(I8,6)-RIGHT(I8,5)=0,"",IF(AND(RIGHT(I8,5)-RIGHT(I8,3)=0,RIGHT(I8,6)-RIGHT(I8,5)>0),VLOOKUP(RIGHT(I8,6)-RIGHT(I8,5),Sheet2!$J$4:$K$12,2)&"Ribu ",VLOOKUP(RIGHT(I8,6)-RIGHT(I8,5),Sheet2!$J$4:$K$12,2))) | P8: =+IF(RIGHT(I8,5)-RIGHT(I8,4)=0,"",IF(AND(RIGHT(I8,5)-RIGHT(I8,4)=10000,VALUE(RIGHT(I8,4))>=1000),VLOOKUP(RIGHT(I8,5)-RIGHT(I8,3),Sheet2!$L$4:$M$12,2),VLOOKUP(RIGHT(I8,5)-RIGHT(I8,4),Sheet2!$N$4:$O$12,2)))&IF(AND(VALUE(RIGHT(I8,4))<1000,RIGHT(I8,5)-RIGHT(I8,4)>0),"Ribu ","") -> Sepuluh Ribu | Q8: =+IF(RIGHT(I8,4)-RIGHT(I8,3)=0,"",IF(RIGHT(I8,5)-RIGHT(I8,4)=10000,"",IF(AND(VALUE(RIGHT(I8,6))>=20000,VALUE(RIGHT(I8,6)-RIGHT(I8,5))<=900000),VLOOKUP(RIGHT(I8,4)-RIGHT(I8,3),Sheet2!$P$4:$Q$12,2),"Seribu "))) | R8: =+IF(RIGHT(I8,3)-RIGHT(I8,2)=0,"",VLOOKUP(RIGHT(I8,3)-RIGHT(I8,2),Sheet2!$R$4:$S$12,2)) -> Seratus | S8: =+IF(RIGHT(I8,2)-RIGHT(I8,1)=0,"",IF(AND(RIGHT(I8,2)-RIGHT(I8,1)=10,VALUE(RIGHT(I8,1))>0),VLOOKUP(VALUE(RIGHT(I8,2)),Sheet2!$X$4:$Y$12,2),VLOOKUP(RIGHT(I8,2)-RIGHT(I8,1),Sheet2!$T$4:$U$12,2))) | T8: =+IF(RIGHT(I8,2)-RIGHT(I8,1)=10,"",IF(VALUE(RIGHT(I8,1))=0,"",VLOOKUP(VALUE(RIGHT(I8,1)),Sheet2!$V$4:$W$12,2))) -> Satu
I9: 54547 | J9: =L9&M9&N9&O9&P9&Q9&R9&S9&T9&"Rupiah" -> Lima Puluh Empat Ribu Lima Ratus Empat Puluh Tujuh Rupiah | L9: =+IF(RIGHT(I9,9)-RIGHT(I9,8)=0,"",IF(RIGHT(I9,8)-RIGHT(I9,6)=0,VLOOKUP(RIGHT(I9,9)-RIGHT(I9,8),Sheet2!$B$4:$C$12,2)&"Juta ",VLOOKUP(RIGHT(I9,9)-RIGHT(I9,8),Sheet2!$B$4:$C$12,2))) | M9: =+IF(RIGHT(I9,8)-RIGHT(I9,7)=0,"",IF(AND(RIGHT(I9,8)-RIGHT(I9,7)=10000000,RIGHT(I9,7)-RIGHT(I9,6)>0),VLOOKUP(RIGHT(I9,8)-RIGHT(I9,6),Sheet2!$D$4:$E$12,2),VLOOKUP(RIGHT(I9,8)-RIGHT(I9,7),Sheet2!$F$4:$G$12,2)))&IF(AND(RIGHT(I9,7)-RIGHT(I9,6)=0,RIGHT(I9,8)-RIGHT(I9,7)>0),"Juta ","") | N9: =+IF(RIGHT(I9,7)-RIGHT(I9,6)=0,"",IF(AND(RIGHT(I9,8)-RIGHT(I9,7)=10000000,RIGHT(I9,7)-RIGHT(I9,6)>0),"",VLOOKUP(RIGHT(I9,7)-RIGHT(I9,6),Sheet2!$H$4:$I$12,2))) | O9: =+IF(RIGHT(I9,6)-RIGHT(I9,5)=0,"",IF(AND(RIGHT(I9,5)-RIGHT(I9,3)=0,RIGHT(I9,6)-RIGHT(I9,5)>0),VLOOKUP(RIGHT(I9,6)-RIGHT(I9,5),Sheet2!$J$4:$K$12,2)&"Ribu ",VLOOKUP(RIGHT(I9,6)-RIGHT(I9,5),Sheet2!$J$4:$K$12,2))) | P9: =+IF(RIGHT(I9,5)-RIGHT(I9,4)=0,"",IF(AND(RIGHT(I9,5)-RIGHT(I9,4)=10000,VALUE(RIGHT(I9,4))>=1000),VLOOKUP(RIGHT(I9,5)-RIGHT(I9,3),Sheet2!$L$4:$M$12,2),VLOOKUP(RIGHT(I9,5)-RIGHT(I9,4),Sheet2!$N$4:$O$12,2)))&IF(AND(VALUE(RIGHT(I9,4))<1000,RIGHT(I9,5)-RIGHT(I9,4)>0),"Ribu ","") -> Lima Puluh | Q9: =+IF(RIGHT(I9,4)-RIGHT(I9,3)=0,"",IF(RIGHT(I9,5)-RIGHT(I9,4)=10000,"",IF(AND(VALUE(RIGHT(I9,6))>=20000,VALUE(RIGHT(I9,6)-RIGHT(I9,5))<=900000),VLOOKUP(RIGHT(I9,4)-RIGHT(I9,3),Sheet2!$P$4:$Q$12,2),"Seribu "))) -> Empat Ribu | R9: =+IF(RIGHT(I9,3)-RIGHT(I9,2)=0,"",VLOOKUP(RIGHT(I9,3)-RIGHT(I9,2),Sheet2!$R$4:$S$12,2)) -> Lima Ratus | S9: =+IF(RIGHT(I9,2)-RIGHT(I9,1)=0,"",IF(AND(RIGHT(I9,2)-RIGHT(I9,1)=10,VALUE(RIGHT(I9,1))>0),VLOOKUP(VALUE(RIGHT(I9,2)),Sheet2!$X$4:$Y$12,2),VLOOKUP(RIGHT(I9,2)-RIGHT(I9,1),Sheet2!$T$4:$U$12,2))) -> Empat Puluh | T9: =+IF(RIGHT(I9,2)-RIGHT(I9,1)=10,"",IF(VALUE(RIGHT(I9,1))=0,"",VLOOKUP(VALUE(RIGHT(I9,1)),Sheet2!$V$4:$W$12,2))) -> Tujuh
I10: 12 | J10: =L10&M10&N10&O10&P10&Q10&R10&S10&T10&"Rupiah" -> Dua Belas Rupiah | L10: =+IF(RIGHT(I10,9)-RIGHT(I10,8)=0,"",IF(RIGHT(I10,8)-RIGHT(I10,6)=0,VLOOKUP(RIGHT(I10,9)-RIGHT(I10,8),Sheet2!$B$4:$C$12,2)&"Juta ",VLOOKUP(RIGHT(I10,9)-RIGHT(I10,8),Sheet2!$B$4:$C$12,2))) | M10: =+IF(RIGHT(I10,8)-RIGHT(I10,7)=0,"",IF(AND(RIGHT(I10,8)-RIGHT(I10,7)=10000000,RIGHT(I10,7)-RIGHT(I10,6)>0),VLOOKUP(RIGHT(I10,8)-RIGHT(I10,6),Sheet2!$D$4:$E$12,2),VLOOKUP(RIGHT(I10,8)-RIGHT(I10,7),Sheet2!$F$4:$G$12,2)))&IF(AND(RIGHT(I10,7)-RIGHT(I10,6)=0,RIGHT(I10,8)-RIGHT(I10,7)>0),"Juta ","") | N10: =+IF(RIGHT(I10,7)-RIGHT(I10,6)=0,"",IF(AND(RIGHT(I10,8)-RIGHT(I10,7)=10000000,RIGHT(I10,7)-RIGHT(I10,6)>0),"",VLOOKUP(RIGHT(I10,7)-RIGHT(I10,6),Sheet2!$H$4:$I$12,2))) | O10: =+IF(RIGHT(I10,6)-RIGHT(I10,5)=0,"",IF(AND(RIGHT(I10,5)-RIGHT(I10,3)=0,RIGHT(I10,6)-RIGHT(I10,5)>0),VLOOKUP(RIGHT(I10,6)-RIGHT(I10,5),Sheet2!$J$4:$K$12,2)&"Ribu ",VLOOKUP(RIGHT(I10,6)-RIGHT(I10,5),Sheet2!$J$4:$K$12,2))) | P10: =+IF(RIGHT(I10,5)-RIGHT(I10,4)=0,"",IF(AND(RIGHT(I10,5)-RIGHT(I10,4)=10000,VALUE(RIGHT(I10,4))>=1000),VLOOKUP(RIGHT(I10,5)-RIGHT(I10,3),Sheet2!$L$4:$M$12,2),VLOOKUP(RIGHT(I10,5)-RIGHT(I10,4),Sheet2!$N$4:$O$12,2)))&IF(AND(VALUE(RIGHT(I10,4))<1000,RIGHT(I10,5)-RIGHT(I10,4)>0),"Ribu ","") | Q10: =+IF(RIGHT(I10,4)-RIGHT(I10,3)=0,"",IF(RIGHT(I10,5)-RIGHT(I10,4)=10000,"",IF(AND(VALUE(RIGHT(I10,6))>=20000,VALUE(RIGHT(I10,6)-RIGHT(I10,5))<=900000),VLOOKUP(RIGHT(I10,4)-RIGHT(I10,3),Sheet2!$P$4:$Q$12,2),"Seribu "))) | R10: =+IF(RIGHT(I10,3)-RIGHT(I10,2)=0,"",VLOOKUP(RIGHT(I10,3)-RIGHT(I10,2),Sheet2!$R$4:$S$12,2)) | S10: =+IF(RIGHT(I10,2)-RIGHT(I10,1)=0,"",IF(AND(RIGHT(I10,2)-RIGHT(I10,1)=10,VALUE(RIGHT(I10,1))>0),VLOOKUP(VALUE(RIGHT(I10,2)),Sheet2!$X$4:$Y$12,2),VLOOKUP(RIGHT(I10,2)-RIGHT(I10,1),Sheet2!$T$4:$U$12,2))) -> Dua Belas | T10: =+IF(RIGHT(I10,2)-RIGHT(I10,1)=10,"",IF(VALUE(RIGHT(I10,1))=0,"",VLOOKUP(VALUE(RIGHT(I10,1)),Sheet2!$V$4:$W$12,2)))
I11: 95443 | J11: =L11&M11&N11&O11&P11&Q11&R11&S11&T11&"Rupiah" -> Sembilan Puluh Lima Ribu Empat Ratus Empat Puluh Tiga Rupiah | L11: =+IF(RIGHT(I11,9)-RIGHT(I11,8)=0,"",IF(RIGHT(I11,8)-RIGHT(I11,6)=0,VLOOKUP(RIGHT(I11,9)-RIGHT(I11,8),Sheet2!$B$4:$C$12,2)&"Juta ",VLOOKUP(RIGHT(I11,9)-RIGHT(I11,8),Sheet2!$B$4:$C$12,2))) | M11: =+IF(RIGHT(I11,8)-RIGHT(I11,7)=0,"",IF(AND(RIGHT(I11,8)-RIGHT(I11,7)=10000000,RIGHT(I11,7)-RIGHT(I11,6)>0),VLOOKUP(RIGHT(I11,8)-RIGHT(I11,6),Sheet2!$D$4:$E$12,2),VLOOKUP(RIGHT(I11,8)-RIGHT(I11,7),Sheet2!$F$4:$G$12,2)))&IF(AND(RIGHT(I11,7)-RIGHT(I11,6)=0,RIGHT(I11,8)-RIGHT(I11,7)>0),"Juta ","") | N11: =+IF(RIGHT(I11,7)-RIGHT(I11,6)=0,"",IF(AND(RIGHT(I11,8)-RIGHT(I11,7)=10000000,RIGHT(I11,7)-RIGHT(I11,6)>0),"",VLOOKUP(RIGHT(I11,7)-RIGHT(I11,6),Sheet2!$H$4:$I$12,2))) | O11: =+IF(RIGHT(I11,6)-RIGHT(I11,5)=0,"",IF(AND(RIGHT(I11,5)-RIGHT(I11,3)=0,RIGHT(I11,6)-RIGHT(I11,5)>0),VLOOKUP(RIGHT(I11,6)-RIGHT(I11,5),Sheet2!$J$4:$K$12,2)&"Ribu ",VLOOKUP(RIGHT(I11,6)-RIGHT(I11,5),Sheet2!$J$4:$K$12,2))) | P11: =+IF(RIGHT(I11,5)-RIGHT(I11,4)=0,"",IF(AND(RIGHT(I11,5)-RIGHT(I11,4)=10000,VALUE(RIGHT(I11,4))>=1000),VLOOKUP(RIGHT(I11,5)-RIGHT(I11,3),Sheet2!$L$4:$M$12,2),VLOOKUP(RIGHT(I11,5)-RIGHT(I11,4),Sheet2!$N$4:$O$12,2)))&IF(AND(VALUE(RIGHT(I11,4))<1000,RIGHT(I11,5)-RIGHT(I11,4)>0),"Ribu ","") -> Sembilan Puluh | Q11: =+IF(RIGHT(I11,4)-RIGHT(I11,3)=0,"",IF(RIGHT(I11,5)-RIGHT(I11,4)=10000,"",IF(AND(VALUE(RIGHT(I11,6))>=20000,VALUE(RIGHT(I11,6)-RIGHT(I11,5))<=900000),VLOOKUP(RIGHT(I11,4)-RIGHT(I11,3),Sheet2!$P$4:$Q$12,2),"Seribu "))) -> Lima Ribu | R11: =+IF(RIGHT(I11,3)-RIGHT(I11,2)=0,"",VLOOKUP(RIGHT(I11,3)-RIGHT(I11,2),Sheet2!$R$4:$S$12,2)) -> Empat Ratus | S11: =+IF(RIGHT(I11,2)-RIGHT(I11,1)=0,"",IF(AND(RIGHT(I11,2)-RIGHT(I11,1)=10,VALUE(RIGHT(I11,1))>0),VLOOKUP(VALUE(RIGHT(I11,2)),Sheet2!$X$4:$Y$12,2),VLOOKUP(RIGHT(I11,2)-RIGHT(I11,1),Sheet2!$T$4:$U$12,2))) -> Empat Puluh | T11: =+IF(RIGHT(I11,2)-RIGHT(I11,1)=10,"",IF(VALUE(RIGHT(I11,1))=0,"",VLOOKUP(VALUE(RIGHT(I11,1)),Sheet2!$V$4:$W$12,2))) -> Tiga
I23: 7101 | J23: =+IF(RIGHT(I23,4)-RIGHT(I23,3)=0,"",VLOOKUP(RIGHT(I23,4)-RIGHT(I23,3),Sheet2!$P$4:$Q$12,2))&IF(RIGHT(I23,3)-RIGHT(I23,2)=0,"",VLOOKUP(RIGHT(I23,3)-RIGHT(I23,2),Sheet2!$R$6:$S$12,2))&IF(RIGHT(I23,2)-RIGHT(I23,1)=0,"",VLOOKUP(RIGHT(I23,2)-RIGHT(I23,1),Sheet2!$T$4:$U$12,2))&IF(VALUE(RIGHT(I23,1))=0,"",VLOOKUP(VALUE(RIGHT(I23,1)),Sheet2!$V$4:$W$12,2))&"Rupiah" -> #N/A
I24: 7000 | J24: =+IF(RIGHT(I24,4)-RIGHT(I24,3)=0,"",VLOOKUP(RIGHT(I24,4)-RIGHT(I24,3),Sheet2!$P$4:$Q$12,2))&IF(RIGHT(I24,3)-RIGHT(I24,2)=0,"",VLOOKUP(RIGHT(I24,3)-RIGHT(I24,2),Sheet2!$R$6:$S$12,2))&IF(RIGHT(I24,2)-RIGHT(I24,1)=0,"",VLOOKUP(RIGHT(I24,2)-RIGHT(I24,1),Sheet2!$T$4:$U$12,2))&IF(VALUE(RIGHT(I24,1))=0,"",VLOOKUP(VALUE(RIGHT(I24,1)),Sheet2!$V$4:$W$12,2))&"Rupiah" -> Tujuh Ribu Rupiah
I25: 9500 | J25: =+IF(RIGHT(I25,4)-RIGHT(I25,3)=0,"",VLOOKUP(RIGHT(I25,4)-RIGHT(I25,3),Sheet2!$P$4:$Q$12,2))&IF(RIGHT(I25,3)-RIGHT(I25,2)=0,"",VLOOKUP(RIGHT(I25,3)-RIGHT(I25,2),Sheet2!$R$6:$S$12,2))&IF(RIGHT(I25,2)-RIGHT(I25,1)=0,"",VLOOKUP(RIGHT(I25,2)-RIGHT(I25,1),Sheet2!$T$4:$U$12,2))&IF(VALUE(RIGHT(I25,1))=0,"",VLOOKUP(VALUE(RIGHT(I25,1)),Sheet2!$V$4:$W$12,2))&"Rupiah" -> Sembilan Ribu Lima Ratus Rupiah | S25: =+VLOOKUP(RIGHT(kwitansi!A19,2)-RIGHT(kwitansi!A19,1),Sheet2!$T$4:$U$12,2) -> #N/A
I26: 71 | J26: =+IF(RIGHT(I26,4)-RIGHT(I26,3)=0,"",VLOOKUP(RIGHT(I26,4)-RIGHT(I26,3),Sheet2!$P$4:$Q$12,2))&IF(RIGHT(I26,3)-RIGHT(I26,2)=0,"",VLOOKUP(RIGHT(I26,3)-RIGHT(I26,2),Sheet2!$R$6:$S$12,2))&IF(RIGHT(I26,2)-RIGHT(I26,1)=0,"",VLOOKUP(RIGHT(I26,2)-RIGHT(I26,1),Sheet2!$T$4:$U$12,2))&IF(VALUE(RIGHT(I26,1))=0,"",VLOOKUP(VALUE(RIGHT(I26,1)),Sheet2!$V$4:$W$12,2))&"Rupiah" -> Tujuh Puluh Satu Rupiah
I27: 4611 | J27: =+IF(RIGHT(I7,4)-RIGHT(I7,3)=0,"",VLOOKUP(RIGHT(I7,4)-RIGHT(I7,3),$S$3:$T$11,2))&IF(RIGHT(I7,3)-RIGHT(I7,2)=0,"",VLOOKUP(RIGHT(I7,3)-RIGHT(I7,2),$U$5:$V$11,2))&IF(RIGHT(I7,2)-RIGHT(I7,1)=0,"",VLOOKUP(RIGHT(I7,2)-RIGHT(I7,1),$W$3:$X$11,2))&IF(VALUE(RIGHT(I7,1))=0,"",VLOOKUP(VALUE(RIGHT(I7,1)),$Y$3:$Z$11,2))&"Rupiah"
I28: 7500 | J28: =+IF(RIGHT(I28,4)-RIGHT(I28,3)=0,"",VLOOKUP(RIGHT(I28,4)-RIGHT(I28,3),Sheet2!$P$4:$Q$12,2))&IF(RIGHT(I28,3)-RIGHT(I28,2)=0,"",VLOOKUP(RIGHT(I28,3)-RIGHT(I28,2),Sheet2!$R$6:$S$12,2))&IF(RIGHT(I28,2)-RIGHT(I28,1)=0,"",VLOOKUP(RIGHT(I28,2)-RIGHT(I28,1),Sheet2!$T$4:$U$12,2))&IF(VALUE(RIGHT(I28,1))=0,"",VLOOKUP(VALUE(RIGHT(I28,1)),Sheet2!$V$4:$W$12,2))&"Rupiah" -> Tujuh Ribu Lima Ratus Rupiah
I30: 7001 | J30: =+IF(RIGHT(I10,4)-RIGHT(I10,3)=0,"",VLOOKUP(RIGHT(I10,4)-RIGHT(I10,3),$M$3:$N$11,2))&IF(RIGHT(I10,3)-RIGHT(I10,2)=0,"",VLOOKUP(RIGHT(I10,3)-RIGHT(I10,2),$O$5:$P$11,2))&IF(RIGHT(I10,2)-RIGHT(I10,1)=0,"",IF(AND(RIGHT(I10,2)-RIGHT(I10,1)=10,VALUE(RIGHT(17,1))>0),VLOOKUP(VALUE(RIGHT(I10,2)),U6:V14,2),VLOOKUP(RIGHT(I10,2)-RIGHT(I10,1),$Q$3:$R$11,2))&IF(RIGHT(I10,2)-RIGHT(I10,1)=10,"",IF(VALUE(RIGHT(I10,1))=0,"",VLOOKUP(VALUE(RIGHT(I10,1)),$S$3:$T$11,2))))&"Rupiah"
J31: =+IF(RIGHT(I31,4)-RIGHT(I31,3)=0,"",VLOOKUP(RIGHT(I31,4)-RIGHT(I31,3),Sheet2!$P$4:$Q$12,2))&IF(RIGHT(I31,3)-RIGHT(I31,2)=0,"",VLOOKUP(RIGHT(I31,3)-RIGHT(I31,2),Sheet2!$R$6:$S$12,2))&IF(RIGHT(I31,2)-RIGHT(I31,1)=0,"",IF(AND(RIGHT(I31,2)-RIGHT(I31,1)=10,VALUE(RIGHT(17,1))>0),VLOOKUP(VALUE(RIGHT(I31,2)),Sheet2!X8:Y16,2),VLOOKUP(RIGHT(I31,2)-RIGHT(I31,1),Sheet2!$T$4:$U$12,2))&IF(RIGHT(I31,2)-RIGHT(I31,1)=10,"",IF(VALUE(RIGHT(I31,1))=0,"",VLOOKUP(VALUE(RIGHT(I31,1)),Sheet2!$V$4:$W$12,2))))&"Rupiah" -> #VALUE!
J32: =+IF(RIGHT(I32,4)-RIGHT(I32,3)=0,"",VLOOKUP(RIGHT(I32,4)-RIGHT(I32,3),Sheet2!$P$4:$Q$12,2))&IF(RIGHT(I32,3)-RIGHT(I32,2)=0,"",VLOOKUP(RIGHT(I32,3)-RIGHT(I32,2),Sheet2!$R$6:$S$12,2))&IF(RIGHT(I32,2)-RIGHT(I32,1)=0,"",IF(AND(RIGHT(I32,2)-RIGHT(I32,1)=10,VALUE(RIGHT(17,1))>0),VLOOKUP(VALUE(RIGHT(I32,2)),Sheet2!X9:Y17,2),VLOOKUP(RIGHT(I32,2)-RIGHT(I32,1),Sheet2!$T$4:$U$12,2))&IF(RIGHT(I32,2)-RIGHT(I32,1)=10,"",IF(VALUE(RIGHT(I32,1))=0,"",VLOOKUP(VALUE(RIGHT(I32,1)),Sheet2!$V$4:$W$12,2))))&"Rupiah" -> #VALUE!
J33: =+IF(RIGHT(I24,4)-RIGHT(I24,3)=0,"",VLOOKUP(RIGHT(I24,4)-RIGHT(I24,3),Sheet2!$P$4:$Q$12,2))&IF(RIGHT(I24,3)-RIGHT(I24,2)=0,"",VLOOKUP(RIGHT(I24,3)-RIGHT(I24,2),Sheet2!$R$4:$S$12,2))&IF(RIGHT(I24,2)-RIGHT(I24,1)=0,"",VLOOKUP(RIGHT(I24,2)-RIGHT(I24,1),Sheet2!$T$4:$U$12,2))&IF(VALUE(RIGHT(I24,1))=0,"",IF(RIGHT(I24,2)-RIGHT(I24,1)=10,"",VLOOKUP(VALUE(RIGHT(I24,1)),Sheet2!$V$4:$W$12,2)))&"Rupiah" -> Tujuh Ribu Rupiah
J34: =+IF(RIGHT(I10,2)-RIGHT(I10,1)=10,"",IF(VALUE(RIGHT(I10,1))=0,"",VLOOKUP(VALUE(RIGHT(I10,1)),$S$3:$T$11,2)))

Sheet TABEL LUNAS
A1: NO | B1: NO FAKTUR | C1: PERUSAHAAN | D1: NILAI | E1: PEMBAYARAN | J1: TUNAI | K1: BCA | L1: MANDIRI | M1: Keterangan | N1: TOTAL/BLN
B2: 11/TQM/WKM/II/12 | C2: PT PERTAMINA RU II | D2: 48392900 | E2: 1. Pelatihan Juri CIP, tanggal 13 - 15 Februari 2012
B3: 12-1/TQM/WKM/II/12 | C3: PT MITRA PINASTIKA MULIA | D3: 3200000 | E3: Pelatihan TQM For QCC Facilitator tgl 21-23 Februari 2012 (AN, Nuyradi)
B4: 12-2/TQM/WKM/II/12 | C4: PT MITRA PINASTIKA MULIA | D4: 3200000 | E4: An : EKO ARUN NOVIANTO #0931#
B5: 12-3/TQM/WKM/II/12 | C5: PT MITRA PINASTIKA MULIA | D5: 3200000 | E5: An : HESTI MARDIANA #0740#
B6: 12-4/TQM/WKM/II/12 | C6: PT MITRA PINASTIKA MULIA | D6: 3200000 | E6: An : RATNA TRI HARTATI #5333#
B7: 10/TQM/WKM/II/12 | C7: PT PERTAMINA GAS | D7: 36130000 | E7: Angkatan I Pelatihan Upskilling J& Penyusunan Risalah Continuous Improvement
B8: 13/TQM/WKM/II/12 | C8: PT PERTAMINA GAS | D8: 74129800 | E8: Angkatan II Pelatihan Upskilling J& Penyusunan Risalah Continuous Improvement
B9: 14/TQM/WKM/II/12 | C9: PT PERTAMINA GAS | D9: 40000000 | E9: Bimbingan Penulisan Makalah "International Convention On Quality
B10: 18/TQM/WKM/III/12 | C10: PT PERTAMINA GAS | D10: 39346000 | E10: Angkatan III Pelatihan "Upskilling & Penyusunan Risalah Continuous
B11: 19/TQM/WKM/III/12 | C11: PT PERTAMINA DRILLING SERVICE | D11: 48058798 | E11: Angkatan I Pelatihan "Upskilling & Penyusunan Risalah Continuous
B12: 08R/TQM/WKM/III/12 | C12: PT PERTAMINA EP | D12: 252450000
B13: 30/TQM/WKM/III/12 | C13: PT KALBE GROUP | D13: 45000000
B14: 32/TQM/WKM/IV/12 | C14: PT PERTAMINA (PERSERO) | D14: 143550000
B15: 36-6/TQM/WKM/IV/12 | C15: PT SEMEN GRESIK (PERSERO) Tbk | D15: 3000000
B16: 37-2/TQM/WKM/IV/12 | C16: PUSKESMAS KECAMATAN CEMPAKA PUTIH | D16: 3300000
B17: 47/TQM/WKM/V/12 | C17: PT PERTAMINA GAS | D17: 33000000
B18: 52/TQM/WKM/V/12 | C18: PT UNTUNG BERSAMA SEJAHTERA | D18: 3500000
B19: 53/TQM/WKM/V/12 | C19: SUDINKES KOTA ADMINISTRASI JAKARTA PUSAT | D19: 3500000
B20: 55-2/TQM/WKM/IV/12 | C20: PT KALTIM PARNA INDUSTRI | D20: 6255600
B21: 78/TQM/WKM/V/12 | C21: PT PUPUK SRIWIDJAJA PALEMBANG | D21: 38500000
B22: 53/TQM/WKM/V/12 | C22: SUKU DINAS KESEHATAN | D22: 7700000
B23: 86/TQM/WKM/VI/12 | C23: PT PERTAMINA GAS | D23: 78000000
... B32: 351/TQM/WKM/XII/12 | C32: PT PERTAMINA GAS | D32: 581171800
B33: =+kwitansi!$J$1 -> 224/TKMPN/WKM/X/2026 | C33: =+kwitansi!$B$3 -> PT WASKITA KARYA (PERSERO) Tbk | D33: =+kwitansi!$A$19 -> 57442500
B34: =+kwitansi!$J$1 -> 224/TKMPN/WKM/X/2026 | C34: =+kwitansi!$B$3 -> PT WASKITA KARYA (PERSERO) Tbk | D34: =+kwitansi!$A$19 -> 57442500
B35: =+kwitansi!$J$1 -> 224/TKMPN/WKM/X/2026 | C35: =+kwitansi!$B$3 -> PT WASKITA KARYA (PERSERO) Tbk | D35: =+kwitansi!$A$19 -> 57442500
B36: =+kwitansi!$J$1 -> 224/TKMPN/WKM/X/2026 | C36: =+kwitansi!$B$3 -> PT WASKITA KARYA (PERSERO) Tbk | D36: =+kwitansi!$A$19 -> 57442500
B37: =+kwitansi!$J$1 -> 224/TKMPN/WKM/X/2026 | C37: =+kwitansi!$B$3 -> PT WASKITA KARYA (PERSERO) Tbk | D37: =+kwitansi!$A$19 -> 57442500
B38: =+kwitansi!$J$1 -> 224/TKMPN/WKM/X/2026 | C38: =+kwitansi!$B$3 -> PT WASKITA KARYA (PERSERO) Tbk | D38: =+kwitansi!$A$19 -> 57442500
B39: =+kwitansi!$J$1 -> 224/TKMPN/WKM/X/2026 | C39: =+kwitansi!$B$3 -> PT WASKITA KARYA (PERSERO) Tbk | D39: =+kwitansi!$A$19 -> 57442500
B40: =+kwitansi!$J$1 -> 224/TKMPN/WKM/X/2026 | C40: =+kwitansi!$B$3 -> PT WASKITA KARYA (PERSERO) Tbk | D40: =+kwitansi!$A$19 -> 57442500
B41: =+kwitansi!$J$1 -> 224/TKMPN/WKM/X/2026 | C41: =+kwitansi!$B$3 -> PT WASKITA KARYA (PERSERO) Tbk | D41: =+kwitansi!$A$19 -> 57442500
B42: =+kwitansi!$J$1 -> 224/TKMPN/WKM/X/2026 | C42: =+kwitansi!$B$3 -> PT WASKITA KARYA (PERSERO) Tbk | D42: =+kwitansi!$A$19 -> 57442500
B43: =+kwitansi!$J$1 -> 224/TKMPN/WKM/X/2026 | C43: =+kwitansi!$B$3 -> PT WASKITA KARYA (PERSERO) Tbk | D43: =+kwitansi!$A$19 -> 57442500
B44: =+kwitansi!$J$1 -> 224/TKMPN/WKM/X/2026 | C44: =+kwitansi!$B$3 -> PT WASKITA KARYA (PERSERO) Tbk | D44: =+kwitansi!$A$19 -> 57442500
... B123: =+kwitansi!$J$1 -> 224/TKMPN/WKM/X/2026 | C123: =+kwitansi!$B$3 -> PT WASKITA KARYA (PERSERO) Tbk | D123: =+kwitansi!$A$19 -> 57442500

Sheet Sheet2
B4: =+R4*1000000 -> 100000000 | C4: =+S4 -> Seratus | D4: =+X4*1000000 -> 11000000 | E4: Sebelas Juta | F4: =+T4*1000000 -> 10000000 | G4: Sepuluh | H4: 1000000 | I4: Satu Juta | J4: 100000 | K4: Seratus | L4: 11000 | M4: Sebelas Ribu | N4: 10000 | O4: Sepuluh | P4: 1000 | Q4: Satu Ribu | R4: 100 | S4: Seratus | T4: 10 | U4: Sepuluh | V4: 1 | W4: Satu | X4: 11 | Y4: Sebelas
B5: =+R5*1000000 -> 200000000 | C5: =+S5 -> Dua Ratus | D5: =+X5*1000000 -> 12000000 | E5: Dua Belas Juta | F5: =+T5*1000000 -> 20000000 | G5: Dua Puluh | H5: =+H4+1000000 -> 2000000 | I5: Dua Juta | J5: =+J4+100000 -> 200000 | K5: Dua Ratus | L5: 12000 | M5: Dua Belas Ribu | N5: =+N4+10000 -> 20000 | O5: Dua Puluh | P5: 2000 | Q5: Dua Ribu | R5: =+R4+100 -> 200 | S5: Dua Ratus | T5: =+T4+10 -> 20 | U5: Dua Puluh | V5: 2 | W5: Dua | X5: =+X4+1 -> 12 | Y5: Dua Belas
B6: =+R6*1000000 -> 300000000 | C6: =+S6 -> Tiga Ratus | D6: =+X6*1000000 -> 13000000 | E6: Tiga Belas Juta | F6: =+T6*1000000 -> 30000000 | G6: Tiga Puluh | H6: =+H5+1000000 -> 3000000 | I6: Tiga Juta | J6: =+J5+100000 -> 300000 | K6: Tiga Ratus | L6: 13000 | M6: Tiga Belas Ribu | N6: =+N5+10000 -> 30000 | O6: Tiga Puluh | P6: 3000 | Q6: Tiga Ribu | R6: =+R5+100 -> 300 | S6: Tiga Ratus | T6: =+T5+10 -> 30 | U6: Tiga Puluh | V6: 3 | W6: Tiga | X6: =+X5+1 -> 13 | Y6: Tiga Belas
B7: =+R7*1000000 -> 400000000 | C7: =+S7 -> Empat Ratus | D7: =+X7*1000000 -> 14000000 | E7: Empat Belas Juta | F7: =+T7*1000000 -> 40000000 | G7: Empat Puluh | H7: =+H6+1000000 -> 4000000 | I7: Empat Juta | J7: =+J6+100000 -> 400000 | K7: Empat Ratus | L7: 14000 | M7: Empat Belas Ribu | N7: =+N6+10000 -> 40000 | O7: Empat Puluh | P7: 4000 | Q7: Empat Ribu | R7: =+R6+100 -> 400 | S7: Empat Ratus | T7: =+T6+10 -> 40 | U7: Empat Puluh | V7: 4 | W7: Empat | X7: =+X6+1 -> 14 | Y7: Empat Belas
B8: =+R8*1000000 -> 500000000 | C8: =+S8 -> Lima Ratus | D8: =+X8*1000000 -> 15000000 | E8: Lima Belas Juta | F8: =+T8*1000000 -> 50000000 | G8: Lima Puluh | H8: =+H7+1000000 -> 5000000 | I8: Lima Juta | J8: =+J7+100000 -> 500000 | K8: Lima Ratus | L8: 15000 | M8: Lima Belas Ribu | N8: =+N7+10000 -> 50000 | O8: Lima Puluh | P8: 5000 | Q8: Lima Ribu | R8: =+R7+100 -> 500 | S8: Lima Ratus | T8: =+T7+10 -> 50 | U8: Lima Puluh | V8: 5 | W8: Lima | X8: =+X7+1 -> 15 | Y8: Lima Belas
B9: =+R9*1000000 -> 600000000 | C9: =+S9 -> Enam Ratus | D9: =+X9*1000000 -> 16000000 | E9: Enam Belas Juta | F9: =+T9*1000000 -> 60000000 | G9: Enam Puluh | H9: =+H8+1000000 -> 6000000 | I9: Enam Juta | J9: =+J8+100000 -> 600000 | K9: Enam Ratus | L9: 16000 | M9: Enam Belas Ribu | N9: =+N8+10000 -> 60000 | O9: Enam Puluh | P9: 6000 | Q9: Enam Ribu | R9: =+R8+100 -> 600 | S9: Enam Ratus | T9: =+T8+10 -> 60 | U9: Enam Puluh | V9: 6 | W9: Enam | X9: =+X8+1 -> 16 | Y9: Enam Belas
B10: =+R10*1000000 -> 700000000 | C10: =+S10 -> Tujuh Ratus | D10: =+X10*1000000 -> 17000000 | E10: Tujuh Belas Juta | F10: =+T10*1000000 -> 70000000 | G10: Tujuh Puluh | H10: =+H9+1000000 -> 7000000 | I10: Tujuh Juta | J10: =+J9+100000 -> 700000 | K10: Tujuh Ratus | L10: 17000 | M10: Tujuh Belas Ribu | N10: =+N9+10000 -> 70000 | O10: Tujuh Puluh | P10: 7000 | Q10: Tujuh Ribu | R10: =+R9+100 -> 700 | S10: Tujuh Ratus | T10: =+T9+10 -> 70 | U10: Tujuh Puluh | V10: 7 | W10: Tujuh | X10: =+X9+1 -> 17 | Y10: Tujuh Belas
B11: =+R11*1000000 -> 800000000 | C11: =+S11 -> Delapan Ratus | D11: =+X11*1000000 -> 18000000 | E11: Delapan Belas Juta | F11: =+T11*1000000 -> 80000000 | G11: Delapan Puluh | H11: =+H10+1000000 -> 8000000 | I11: Delapan Juta | J11: =+J10+100000 -> 800000 | K11: Delapan Ratus | L11: 18000 | M11: Delapan Belas Ribu | N11: =+N10+10000 -> 80000 | O11: Delapan Puluh | P11: 8000 | Q11: Delapan Ribu | R11: =+R10+100 -> 800 | S11: Delapan Ratus | T11: =+T10+10 -> 80 | U11: Delapan Puluh | V11: 8 | W11: Delapan | X11: =+X10+1 -> 18 | Y11: Delapan Belas
B12: =+R12*1000000 -> 900000000 | C12: =+S12 -> Sembilan Ratus | D12: =+X12*1000000 -> 19000000 | E12: Sembilan Belas Juta | F12: =+T12*1000000 -> 90000000 | G12: Sembilan Puluh | H12: =+H11+1000000 -> 9000000 | I12: Sembilan Juta | J12: =+J11+100000 -> 900000 | K12: Sembilan Ratus | L12: 19000 | M12: Sembilan Belas Ribu | N12: =+N11+10000 -> 90000 | O12: Sembilan Puluh | P12: 9000 | Q12: Sembilan Ribu | R12: =+R11+100 -> 900 | S12: Sembilan Ratus | T12: =+T11+10 -> 90 | U12: Sembilan Puluh | V12: 9 | W12: Sembilan | X12: =+X11+1 -> 19 | Y12: Sembilan Belas

Sheet kas
H1: 133600000
H2: 40000000
B4: 39410 | C4: Kas | D4: 1850000 | F4: =+D4-E4 -> 1850000
C5: Kas | D5: 15000000 | F5: =+F4+D5-E5 -> 16850000
C6: hart0n0 | E6: 5000000 | F6: =+F5+D6-E6 -> 11850000
B7: 39411 | C7: Airport taax | E7: 210000 | F7: =+F6+D7-E7 -> 11640000
C8: Rotiboy | E8: 52000 | F8: =+F7+D8-E8 -> 11588000 | H8: =+H1-H2-H3-H4-H5-H6-H7 -> 93600000
C9: Aqua | E9: 16000 | F9: =+F8+D9-E9 -> 11572000
C10: pipit | E10: 2000000 | F10: =+F9+D10-E10 -> 9572000
C11: pulsa | E11: 118000 | F11: =+F10+D11-E11 -> 9454000
C12: Hp 2 | E12: 1600000 | F12: =+F11+D12-E12 -> 7854000
C13: USB 5 | E13: 400000 | F13: =+F12+D13-E13 -> 7454000
C14: Minuman + snack | E14: 52000 | F14: =+F13+D14-E14 -> 7402000
C15: Rita gaji | E15: 500000 | F15: =+F14+D15-E15 -> 6902000
B16: 26/11/207 | C16: PT Telkom | D16: 53200000 | F16: =+F15+D16-E16 -> 60102000
C17: UP V | D17: 70600000 | F17: =+F16+D17-E17 -> 130702000
C18: Ambil di \ATM | D18: 2000000 | F18: =+F17+D18-E18 -> 132702000
F19: =+F18+D19-E19 -> 132702000
C20: Materai | E20: 900000 | F20: =+F19+D20-E20 -> 131802000
C21: Gantungan name taq | E21: 300000 | F21: =+F20+D21-E21 -> 131502000
C22: udin | E22: 1000000 | F22: =+F21+D22-E22 -> 130502000
C23: yopi | E23: 7000000 | F23: =+F22+D23-E23 -> 123502000
C24: Yuniari | D24: 2000000 | F24: =+F23+D24-E24 -> 125502000
C25: agus | D25: 3500000 | F25: =+F24+D25-E25 -> 129002000
C26: Cetakan | E26: 5000000 | F26: =+F25+D26-E26 -> 124002000
C27: Maruli | E27: 1000000 | F27: =+F26+D27-E27 -> 123002000
C28: Parni | E28: 1000000 | F28: =+F27+D28-E28 -> 122002000
C29: Thoriq | E29: 2000000 | F29: =+F28+D29-E29 -> 120002000
C30: Kuswanto | E30: 2000000 | F30: =+F29+D30-E30 -> 118002000
C31: Harmon | E31: 2000000 | F31: =+F30+D31-E31 -> 116002000
C32: Bambang | E32: 1000000 | F32: =+F31+D32-E32 -> 115002000
C33: transport filman | E33: 400000 | F33: =+F32+D33-E33 -> 114602000
C34: Fotocopy n mouse | E34: 400000 | F34: =+F33+D34-E34 -> 114202000
B35: 39413 | C35: Erna/mitra | D35: 3500000 | F35: =+F34+D35-E35 -> 117702000
C36: udin | E36: 1000000 | F36: =+F35+D36-E36 -> 116702000
C37: Diskon Gs Bttreai | E37: 1225000 | F37: =+F36+D37-E37 -> 115477000
C38: Upms IV | D38: 20300000 | F38: =+F37+D38-E38 -> 135777000
C39: Smart | D39: 2250000 | F39: =+F38+D39-E39 -> 138027000
C40: Pipuk kujang | D40: 2000000 | F40: =+F39+D40-E40 -> 140027000
C41: novar | E41: 1000000 | F41: =+F40+D41-E41 -> 139027000
...

Sheet Sheet3
K5: 054-2/TKMPN/WKM-P/VIII/06
F8: PT ASTRA INTERNATIONAL Tbk - HONDA SALES OPERATION
E10: ="# "&Sheet1!L6&Sheet1!M6&Sheet1!N6&Sheet1!O6&Sheet1!P6&Sheet1!Q6&Sheet1!R6&Sheet1!S6&Sheet1!T6&"Rupiah"&" #" -> # Sepuluh Juta Lima Puluh Empat Ribu Empat Ratus Rupiah #
E12: TKMPN-X tanggal 28 November - 2 Desember 2006 di Hotel Natour Garuda
F13: Peserta Penyaji | G13: 6 | H13: org | I13: x | J13: Rp. | K13: 3000000 | L13: =+G13*K13 -> 18000000
F14: Peserta Peninjau | G14: 1 | H14: org | I14: x | J14: Rp. | K14: 3500000 | L14: =+G14*K14 -> 3500000
F15: Wisata | G15: 11 | H15: org | I15: x | J15: Rp. | K15: 500000 | L15: =+G15*K15 -> 5500000
F16: Penginapan CI : tgl 28/11/06 - | G16: 6 | H16: kmr | I16: 5 | J16: mlm | K16: 375000 | L16: =+G16*I16*K16 -> 11250000
F17: CO tgl. 3/12/06 | L17: =SUM(L13:L16) -> 38250000
K18: 29 Agustus 20006
A20: 27500000 | K20: Indah Budiwati
K21: Keuangan

Sheet Sheet4
B3: 25 | D3: 52,5
B4: 27,5 | D4: 82,5
B5: 37,5 | D5: -
B6: 62,5 | D6: 72,5
B7: 35 | D7: -
B8: 37,5 | D8: 62,5
B9: 12,5 | D9: -
B10: 20 | D10: 65
B11: 22,5 | D11: 27,5
B12: 27,5 | D12: -
B13: 37,5 | D13: 37,5 | J13: 7500000 | K13: 6
B14: 42,5 | D14: 57,5
B15: 42,5 | D15: 72,5 | J15: =J13*K13 -> 45000000
B16: 45 | D16: 67,5
B17: 50 | D17: 40
B18: 50 | D18: 57,5
B19: 37,5 | D19: 47,5
B20: 50 | D20: 47,5
B21: 45 | D21: -
B22: 20 | D22: 50
B23: 42,5 | D23: 60,5
B24: 32,5 | D24: 27,5
B25: 50 | D25: 62,5
B26: - | D26: 57,5
B27: - | D27: 70
B28: - | D28: 57,5
B29: - | D29: 57,5
B30: - | D30: 62,5
B31: - | D31: 50
B32: - | D32: 52,5
B33: - | D33: 52,5
B34: =AVERAGE(B3:B33) -> 39 | D34: =AVERAGE(D3:D32) -> 55
